Workbook

Sheet 3.52
B3: Введіть дату | C3: =TODAY() -> 46229
B4: Число цієї дати: | C4: =DAY(C3) -> 26
B5: Місяць у цій даті: | C5: =MONTH(C3) -> 7
B6: Рік у цій даті: | C6: =YEAR(C3) -> 2026

Sheet 3.54
A3: Дата кінця | B3: =DATE(2023,9,17) -> 45186 | C3: =TODAY() -> 46229
A4: Дата Початку | B4: =DATE(2012,5,17) -> 41046 | C4: =DATE(2012,5,17) -> 41046
A5: Кількість років | B5: =DATEDIF(B4,B3,"y") -> 11 | C5: =DATEDIF(C4,C3,"y") -> 14 | D5: =DAYS(C3,C4) -> 5183 | E5: =DATEDIF(B4,B3,"yd") -> 123
A6: Кількість місяців | B6: =DATEDIF(B4,B3, "ym") -> 4 | C6: =DATEDIF(C4,C3, "ym") -> 2
A7: Кількість днів | B7: =DATEDIF(B4,B3, "md") -> 0 | C7: =DATEDIF(C4,C3, "md") -> 9
B8: =concatenate("Різниця між датами це " ,B5, " років ",B6," місяців та ",B7," днів") -> Різниця між датами це 11 років 4 місяців та 0 днів | C8: =concatenate("Різниця між датами це " ,C5, " років ",C6," місяців та ",C7," днів") -> Різниця між датами це 14 років 2 місяців та 9 днів

Sheet 3.60
A1: Дата сьогодення: | B1: =TODAY() -> 46229 | C1: =TEXT(WEEKDAY(B1),"ddddd") -> неділя | D1: =EDATE(B1,4) -> 46352
A2: Кількість днів до сьогоднішнього: | B2: =B1-5 -> 46224
A3: Шуканий номер дня: | B3: =TEXT(WEEKDAY(B2),"ddddd") -> вівторок

Sheet 3.62
A1: Сьогоднішня дата | B1: =TODAY() -> 46229
A2: Мій вік | B2: =DATE(2004,12,23) -> 38344
A3: Кількість днів | B3: =DATEDIF($B$2,$B$1,"D") -> 7885
A4: Кількість місяців | B4: =DATEDIF($B$2,$B$1,"m") -> 259
A5: Кількість тижднів | B5: =DATEDIF($B$2,$B$1,"M")*4 -> 1036

Sheet 3.74
A1: 1 час | B1: =TIME(11,40,59) -> 0.48679398
A2: 2 час | B2: =TIME(13,14,2) -> 0.55141204
A3: Їх різниця | B3: =B2-B1 -> 0.064618056
A4: Їх різниця в секундах | B4: =HOUR(B3)*360+MINUTE(B3)*60+SECOND(B3) -> 2343

Sheet 3.97
A1: No уроку | B1: Початок уроку | C1: Кінець уроку | D1: Перерва
A2: 1 | B2: 0.35416667 | C2: 0.38541667
D3: 0.010416667
A4: 2 | B4: 0.38888889 | C4: 0.42013889
D5: 0.010416667
A6: 3 | B6: 0.43055556 | C6: 0.46180556
D7: 0.010416667
A8: 4 | B8: 0.47222222 | C8: 0.50347222
D9: 0.013888889
A10: 5 | B10: 0.51736111 | C10: 0.54861111
D11: 0.0069444444
A12: 6 | B12: 0.55555556 | C12: 0.58680556
D13: 0.010416667
A14: 7 | B14: 0.59722222 | C14: 0.62847222
D15: 0.0069444444
A16: 8 | B16: 0.63541667 | C16: 0.66666667
A18: Тривалість уроку: | B18: =C2-B2 -> 0.03125 | C18: хвилин

Sheet 1 text
A1: Фамилия | B1: Имя | C1: Отчество | E1: ПІБ | F1: Прізвище та ініціали
A2: Епифанов | B2: Иван | C2: Алексеевич | E2: =A2&" "&B2&" "&C2 -> Епифанов Иван Алексеевич | F2: =A2&" "&left(B2)&"."&LEFT(C2) -> Епифанов И.А
A3: Балочкин | B3: Игорь | C3: Вадимович | E3: =A3&" "&B3&" "&C3 -> Балочкин Игорь Вадимович | F3: =A3&" "&left(B3)&"."&LEFT(C3) -> Балочкин И.В
A4: Кувшинов | B4: Виктор | C4: Евгеньевич | E4: =A4&" "&B4&" "&C4 -> Кувшинов Виктор Евгеньевич | F4: =A4&" "&left(B4)&"."&LEFT(C4) -> Кувшинов В.Е
A5: Бобошко | B5: Максим | C5: Михайлович | E5: =A5&" "&B5&" "&C5 -> Бобошко Максим Михайлович | F5: =A5&" "&left(B5)&"."&LEFT(C5) -> Бобошко М.М
A6: Павлюкова | B6: Елизавета | C6: Владимировна | E6: =A6&" "&B6&" "&C6 -> Павлюкова Елизавета Владимировна | F6: =A6&" "&left(B6)&"."&LEFT(C6) -> Павлюкова Е.В
A7: Гаврилюк | B7: Юрий | C7: Валентинович | E7: =A7&" "&B7&" "&C7 -> Гаврилюк Юрий Валентинович | F7: =A7&" "&left(B7)&"."&LEFT(C7) -> Гаврилюк Ю.В
A8: Изотова | B8: Ирина | C8: Александровна | E8: =A8&" "&B8&" "&C8 -> Изотова Ирина Александровна | F8: =A8&" "&left(B8)&"."&LEFT(C8) -> Изотова И.А
A9: Сторожев | B9: Олег | C9: Игоревич | E9: =A9&" "&B9&" "&C9 -> Сторожев Олег Игоревич | F9: =A9&" "&left(B9)&"."&LEFT(C9) -> Сторожев О.И
A10: Спивак | B10: Максим | C10: Игоревич | E10: =A10&" "&B10&" "&C10 -> Спивак Максим Игоревич | F10: =A10&" "&left(B10)&"."&LEFT(C10) -> Спивак М.И
A11: Спивак | B11: Максим | C11: Игоревич | E11: =A11&" "&B11&" "&C11 -> Спивак Максим Игоревич | F11: =A11&" "&left(B11)&"."&LEFT(C11) -> Спивак М.И
A12: Епифанов | B12: Иван | C12: Алексеевич | E12: =A12&" "&B12&" "&C12 -> Епифанов Иван Алексеевич | F12: =A12&" "&left(B12)&"."&LEFT(C12) -> Епифанов И.А
A13: Дуганов | B13: Костя | C13: Вячеславович | E13: =A13&" "&B13&" "&C13 -> Дуганов Костя Вячеславович | F13: =A13&" "&left(B13)&"."&LEFT(C13) -> Дуганов К.В
... A104: Климко | B104: Анастасия | C104: Юрьевна | E104: =A104&" "&B104&" "&C104 -> Климко Анастасия Юрьевна | F104: =A104&" "&left(B104)&"."&LEFT(C104) -> Климко А.Ю
A105: Исаков | B105: Богдан | E105: =A105&" "&B105&" "&C105 -> Исаков Богдан | F105: =A105&" "&left(B105)&"."&LEFT(C105) -> Исаков Б.

Sheet 2 text
A1: Телефон | B1: Телефон без зайвих символів
A2: 509756324 | B2: =right(A2,9) -> 509756324 | C2: =right(A2,7) -> 9756324 | D2: 509756324 | E2: 9756324
A3: 972175876 | B3: =right(A3,9) -> 972175876 | C3: =right(A3,7) -> 2175876 | D3: 972175876 | E3: 2175876 | I3: не понимаю что ме делать с форматами и как мне их вітсавить
A4: 974847540 | B4: =right(A4,9) -> 974847540 | C4: =right(A4,7) -> 4847540 | D4: 974847540 | E4: 4847540
A5: 677235957 | B5: =right(A5,9) -> 677235957 | C5: =right(A5,7) -> 7235957 | D5: 677235957 | E5: 7235957
A6: +380679221389 | B6: =right(A6,9) -> 679221389 | C6: =right(A6,7) -> 9221389 | D6: 679221389 | E6: 9221389
A7: +380685008696 | B7: =right(A7,9) -> 685008696 | C7: =right(A7,7) -> 5008696 | D7: 685008696 | E7: 5008696
A8: +380668805222 | B8: =right(A8,9) -> 668805222 | C8: =right(A8,7) -> 8805222 | D8: 668805222 | E8: 8805222
A9: +380637352238 | B9: =right(A9,9) -> 637352238 | C9: =right(A9,7) -> 7352238 | D9: 637352238 | E9: 7352238
A10: 673961683 | B10: =right(A10,9) -> 673961683 | C10: =right(A10,7) -> 3961683 | D10: 673961683 | E10: 3961683
A11: +380674177621 | B11: =right(A11,9) -> 674177621 | C11: =right(A11,7) -> 4177621 | D11: 674177621 | E11: 4177621
A12: +380990181270 | B12: =right(A12,9) -> 990181270 | C12: =right(A12,7) -> 0181270 | D12: 990181270 | E12: 181270
A13: +380980424742 | B13: =right(A13,9) -> 980424742 | C13: =right(A13,7) -> 0424742 | D13: 980424742 | E13: 424742
A14: 683898299 | B14: =right(A14,9) -> 683898299 | C14: =right(A14,7) -> 3898299 | D14: 683898299 | E14: 3898299
A15: 982204010 | B15: =right(A15,9) -> 982204010 | C15: =right(A15,7) -> 2204010 | D15: 982204010 | E15: 2204010
A16: 380969205729 | B16: =right(A16,9) -> 969205729 | C16: =right(A16,7) -> 9205729 | D16: 969205729 | E16: 9205729
A17: 960790437 | B17: =right(A17,9) -> 960790437 | C17: =right(A17,7) -> 0790437 | D17: 960790437 | E17: 790437
A18: 667437733 | B18: =right(A18,9) -> 667437733 | C18: =right(A18,7) -> 7437733 | D18: 667437733 | E18: 7437733
A19: 982141839 | B19: =right(A19,9) -> 982141839 | C19: =right(A19,7) -> 2141839 | D19: 982141839 | E19: 2141839
A20: 972168316 | B20: =right(A20,9) -> 972168316 | C20: =right(A20,7) -> 2168316 | D20: 972168316 | E20: 2168316
A21: 997718190 | B21: =right(A21,9) -> 997718190 | C21: =right(A21,7) -> 7718190 | D21: 997718190 | E21: 7718190
A22: 050-495-15-85 | B22: =right(A22,9) -> 495-15-85 | C22: =right(A22,7) -> 5-15-85 | D22: 495-15-85 | E22: 5-15-85
A23: 6678553582 | B23: =right(A23,9) -> 678553582 | C23: =right(A23,7) -> 8553582 | D23: 678553582 | E23: 8553582
A24: 963579004 | B24: =right(A24,9) -> 963579004 | C24: =right(A24,7) -> 3579004 | D24: 963579004 | E24: 3579004
A25: +380988690452 | B25: =right(A25,9) -> 988690452 | C25: =right(A25,7) -> 8690452 | D25: 988690452 | E25: 8690452
A26: +380666347028 | B26: =right(A26,9) -> 666347028 | C26: =right(A26,7) -> 6347028 | D26: 666347028 | E26: 6347028
A27: 949323072 | B27: =right(A27,9) -> 949323072 | C27: =right(A27,7) -> 9323072 | D27: 949323072 | E27: 9323072
A28: 380972929706 | B28: =right(A28,9) -> 972929706 | C28: =right(A28,7) -> 2929706 | D28: 972929706 | E28: 2929706
A29: 067-723-06-87 | B29: =right(A29,9) -> 723-06-87 | C29: =right(A29,7) -> 3-06-87 | D29: 723-06-87 | E29: 31931
A30: 380984989647 | B30: =right(A30,9) -> 984989647 | C30: =right(A30,7) -> 4989647 | D30: 984989647 | E30: 4989647
A31: 631361567 | B31: =right(A31,9) -> 631361567 | C31: =right(A31,7) -> 1361567 | D31: 631361567 | E31: 1361567
A32: 679209211 | B32: =right(A32,9) -> 679209211 | C32: =right(A32,7) -> 9209211 | D32: 679209211 | E32: 9209211
A33: 674880197 | B33: =right(A33,9) -> 674880197 | C33: =right(A33,7) -> 4880197 | D33: 674880197 | E33: 4880197
A34: 505130125 | B34: =right(A34,9) -> 505130125 | C34: =right(A34,7) -> 5130125 | D34: 505130125 | E34: 5130125
A35: 509792811 | B35: =right(A35,9) -> 509792811 | C35: =right(A35,7) -> 9792811 | D35: 509792811 | E35: 9792811
A36: +380674861520 | B36: =right(A36,9) -> 674861520 | C36: =right(A36,7) -> 4861520 | D36: 674861520 | E36: 4861520
A37: 666187270 | B37: =right(A37,9) -> 666187270 | C37: =right(A37,7) -> 6187270 | D37: 666187270 | E37: 6187270
A38: +380681228716 | B38: =right(A38,9) -> 681228716 | C38: =right(A38,7) -> 1228716 | D38: 681228716 | E38: 1228716
A39: +380949494201 | B39: =right(A39,9) -> 949494201 | C39: =right(A39,7) -> 9494201 | D39: 949494201 | E39: 9494201
A40: 671180518 | B40: =right(A40,9) -> 671180518 | C40: =right(A40,7) -> 1180518 | D40: 671180518 | E40: 1180518
...

Sheet 3 text
B1: Телефон
B2: 9756324 | C2: =IFS(LEN(B2)=6,CONCAT("0482",B2),LEN(B2)=7,CONCAT("048",B2)) -> 0489756324 | D2: 489756324
B3: 2175876 | C3: =IFS(LEN(B3)=6,CONCAT("0482",B3),LEN(B3)=7,CONCAT("048",B3)) -> 0482175876 | D3: 482175876 | I3: =LEN(B2) -> 7
B4: 4847540 | C4: =IFS(LEN(B4)=6,CONCAT("0482",B4),LEN(B4)=7,CONCAT("048",B4)) -> 0484847540 | D4: 484847540
B5: 7235957 | C5: =IFS(LEN(B5)=6,CONCAT("0482",B5),LEN(B5)=7,CONCAT("048",B5)) -> 0487235957 | D5: 487235957
B6: 9221389 | C6: =IFS(LEN(B6)=6,CONCAT("0482",B6),LEN(B6)=7,CONCAT("048",B6)) -> 0489221389 | D6: 489221389
B7: 5008696 | C7: =IFS(LEN(B7)=6,CONCAT("0482",B7),LEN(B7)=7,CONCAT("048",B7)) -> 0485008696 | D7: 485008696
B8: 8805222 | C8: =IFS(LEN(B8)=6,CONCAT("0482",B8),LEN(B8)=7,CONCAT("048",B8)) -> 0488805222 | D8: 488805222
B9: 7352238 | C9: =IFS(LEN(B9)=6,CONCAT("0482",B9),LEN(B9)=7,CONCAT("048",B9)) -> 0487352238 | D9: 487352238
B10: 3961683 | C10: =IFS(LEN(B10)=6,CONCAT("0482",B10),LEN(B10)=7,CONCAT("048",B10)) -> 0483961683 | D10: 483961683
B11: 3961683 | C11: =IFS(LEN(B11)=6,CONCAT("0482",B11),LEN(B11)=7,CONCAT("048",B11)) -> 0483961683 | D11: 483961683
B12: 9756324 | C12: =IFS(LEN(B12)=6,CONCAT("0482",B12),LEN(B12)=7,CONCAT("048",B12)) -> 0489756324 | D12: 489756324
B13: 4177621 | C13: =IFS(LEN(B13)=6,CONCAT("0482",B13),LEN(B13)=7,CONCAT("048",B13)) -> 0484177621 | D13: 484177621
B14: 181270 | C14: =IFS(LEN(B14)=6,CONCAT("0482",B14),LEN(B14)=7,CONCAT("048",B14)) -> 0482181270 | D14: 482181270
B15: 424742 | C15: =IFS(LEN(B15)=6,CONCAT("0482",B15),LEN(B15)=7,CONCAT("048",B15)) -> 0482424742 | D15: 482424742
... B24: 7718190 | C24: =IFS(LEN(B24)=6,CONCAT("0482",B24),LEN(B24)=7,CONCAT("048",B24)) -> 0487718190 | D24: 487718190
B25: 5-15-85 | C25: =IFS(LEN(B25)=6,CONCAT("0482",B25),LEN(B25)=7,CONCAT("048",B25)) -> 0485-15-85 | D25: 0485-15-85
B26: 8553582 | C26: =IFS(LEN(B26)=6,CONCAT("0482",B26),LEN(B26)=7,CONCAT("048",B26)) -> 0488553582 | D26: 488553582
B27: 3579004 | C27: =IFS(LEN(B27)=6,CONCAT("0482",B27),LEN(B27)=7,CONCAT("048",B27)) -> 0483579004 | D27: 483579004
B28: 8690452 | C28: =IFS(LEN(B28)=6,CONCAT("0482",B28),LEN(B28)=7,CONCAT("048",B28)) -> 0488690452 | D28: 488690452
B29: 6347028 | C29: =IFS(LEN(B29)=6,CONCAT("0482",B29),LEN(B29)=7,CONCAT("048",B29)) -> 0486347028 | D29: 486347028
B30: 9323072 | C30: =IFS(LEN(B30)=6,CONCAT("0482",B30),LEN(B30)=7,CONCAT("048",B30)) -> 0489323072 | D30: 489323072
B31: 2929706 | C31: =IFS(LEN(B31)=6,CONCAT("0482",B31),LEN(B31)=7,CONCAT("048",B31)) -> 0482929706 | D31: 482929706
B32: 31931 | C32: =IFS(LEN(B32)=6,CONCAT("0482",B32),LEN(B32)=7,CONCAT("048",B32)) -> #N/A | D32: #N/A
B33: 4989647 | C33: =IFS(LEN(B33)=6,CONCAT("0482",B33),LEN(B33)=7,CONCAT("048",B33)) -> 0484989647 | D33: 484989647
B34: 1361567 | C34: =IFS(LEN(B34)=6,CONCAT("0482",B34),LEN(B34)=7,CONCAT("048",B34)) -> 0481361567 | D34: 481361567
B35: 9209211 | C35: =IFS(LEN(B35)=6,CONCAT("0482",B35),LEN(B35)=7,CONCAT("048",B35)) -> 0489209211 | D35: 489209211
B36: 4880197 | C36: =IFS(LEN(B36)=6,CONCAT("0482",B36),LEN(B36)=7,CONCAT("048",B36)) -> 0484880197 | D36: 484880197
B37: 5130125 | C37: =IFS(LEN(B37)=6,CONCAT("0482",B37),LEN(B37)=7,CONCAT("048",B37)) -> 0485130125 | D37: 485130125
B38: 9792811 | C38: =IFS(LEN(B38)=6,CONCAT("0482",B38),LEN(B38)=7,CONCAT("048",B38)) -> 0489792811 | D38: 489792811
B39: 4861520 | C39: =IFS(LEN(B39)=6,CONCAT("0482",B39),LEN(B39)=7,CONCAT("048",B39)) -> 0484861520 | D39: 484861520
B40: 6187270 | C40: =IFS(LEN(B40)=6,CONCAT("0482",B40),LEN(B40)=7,CONCAT("048",B40)) -> 0486187270 | D40: 486187270
B41: 1228716 | C41: =IFS(LEN(B41)=6,CONCAT("0482",B41),LEN(B41)=7,CONCAT("048",B41)) -> 0481228716 | D41: 481228716
B42: 9494201 | C42: =IFS(LEN(B42)=6,CONCAT("0482",B42),LEN(B42)=7,CONCAT("048",B42)) -> 0489494201 | D42: 489494201
B43: 1180518 | C43: =IFS(LEN(B43)=6,CONCAT("0482",B43),LEN(B43)=7,CONCAT("048",B43)) -> 0481180518 | D43: 481180518
B44: 7164943 | C44: =IFS(LEN(B44)=6,CONCAT("0482",B44),LEN(B44)=7,CONCAT("048",B44)) -> 0487164943 | D44: 487164943
... B47: 9763553 | C47: =IFS(LEN(B47)=6,CONCAT("0482",B47),LEN(B47)=7,CONCAT("048",B47)) -> 0489763553 | D47: 489763553
B48: -32-702 | C48: =IFS(LEN(B48)=6,CONCAT("0482",B48),LEN(B48)=7,CONCAT("048",B48)) -> 048-32-702 | D48: 048-32-702
B49: 865611 | C49: =IFS(LEN(B49)=6,CONCAT("0482",B49),LEN(B49)=7,CONCAT("048",B49)) -> 0482865611 | D49: 482865611
B50: 1-13-05 | C50: =IFS(LEN(B50)=6,CONCAT("0482",B50),LEN(B50)=7,CONCAT("048",B50)) -> 0481-13-05 | D50: 0481-13-05
...

Sheet 4 text
B1: ПІБ | C1: Телефон | D1: Телефон
B2: ='Аркуш11'!C2&" "&'Аркуш11'!D2&" "&'Аркуш11'!E2 -> Епифанов Иван Алексеевич | C2: ='Аркуш11'!K2 -> 9756324 | D2: 9756324 | E2: =IFS(LEN(D2)=6,CONCAT("0482",D2),LEN(D2)=7,CONCAT("048",D2)) -> 0489756324 | F2: 489756324
B3: ='Аркуш11'!C3&" "&'Аркуш11'!D3&" "&'Аркуш11'!E3 -> Балочкин Игорь Вадимович | C3: ='Аркуш11'!K3 -> 2175876 | D3: 2175876 | E3: =IFS(LEN(D3)=6,CONCAT("0482",D3),LEN(D3)=7,CONCAT("048",D3)) -> 0482175876 | F3: 482175876
B4: ='Аркуш11'!C4&" "&'Аркуш11'!D4&" "&'Аркуш11'!E4 -> Кувшинов Виктор Евгеньевич | C4: ='Аркуш11'!K4 -> 4847540 | D4: 4847540 | E4: =IFS(LEN(D4)=6,CONCAT("0482",D4),LEN(D4)=7,CONCAT("048",D4)) -> 0484847540 | F4: 484847540
B5: ='Аркуш11'!C5&" "&'Аркуш11'!D5&" "&'Аркуш11'!E5 -> Бобошко Максим Михайлович | C5: ='Аркуш11'!K5 -> 7235957 | D5: 7235957 | E5: =IFS(LEN(D5)=6,CONCAT("0482",D5),LEN(D5)=7,CONCAT("048",D5)) -> 0487235957 | F5: 487235957
B6: ='Аркуш11'!C6&" "&'Аркуш11'!D6&" "&'Аркуш11'!E6 -> Павлюкова Елизавета Владимировна | C6: ='Аркуш11'!K6 -> 9221389 | D6: 9221389 | E6: =IFS(LEN(D6)=6,CONCAT("0482",D6),LEN(D6)=7,CONCAT("048",D6)) -> 0489221389 | F6: 489221389
B7: ='Аркуш11'!C7&" "&'Аркуш11'!D7&" "&'Аркуш11'!E7 -> Гаврилюк Юрий Валентинович | C7: ='Аркуш11'!K7 -> 5008696 | D7: 5008696 | E7: =IFS(LEN(D7)=6,CONCAT("0482",D7),LEN(D7)=7,CONCAT("048",D7)) -> 0485008696 | F7: 485008696
B8: ='Аркуш11'!C8&" "&'Аркуш11'!D8&" "&'Аркуш11'!E8 -> Изотова Ирина Александровна | C8: ='Аркуш11'!K8 -> 8805222 | D8: 8805222 | E8: =IFS(LEN(D8)=6,CONCAT("0482",D8),LEN(D8)=7,CONCAT("048",D8)) -> 0488805222 | F8: 488805222
B9: ='Аркуш11'!C9&" "&'Аркуш11'!D9&" "&'Аркуш11'!E9 -> Сторожев Олег Игоревич | C9: ='Аркуш11'!K9 -> 7352238 | D9: 7352238 | E9: =IFS(LEN(D9)=6,CONCAT("0482",D9),LEN(D9)=7,CONCAT("048",D9)) -> 0487352238 | F9: 487352238
B10: ='Аркуш11'!C10&" "&'Аркуш11'!D10&" "&'Аркуш11'!E10 -> Спивак Максим Игоревич | C10: ='Аркуш11'!K10 -> 3961683 | D10: 3961683 | E10: =IFS(LEN(D10)=6,CONCAT("0482",D10),LEN(D10)=7,CONCAT("048",D10)) -> 0483961683 | F10: 483961683
B11: ='Аркуш11'!C11&" "&'Аркуш11'!D11&" "&'Аркуш11'!E11 -> Спивак Максим Игоревич | C11: ='Аркуш11'!K11 -> 3961683 | D11: 3961683 | E11: =IFS(LEN(D11)=6,CONCAT("0482",D11),LEN(D11)=7,CONCAT("048",D11)) -> 0483961683 | F11: 483961683
B12: ='Аркуш11'!C12&" "&'Аркуш11'!D12&" "&'Аркуш11'!E12 -> Епифанов Иван Алексеевич | C12: ='Аркуш11'!K12 -> 9756324 | D12: 9756324 | E12: =IFS(LEN(D12)=6,CONCAT("0482",D12),LEN(D12)=7,CONCAT("048",D12)) -> 0489756324 | F12: 489756324
B13: ='Аркуш11'!C13&" "&'Аркуш11'!D13&" "&'Аркуш11'!E13 -> Дуганов Костя Вячеславович | C13: ='Аркуш11'!K13 -> 4177621 | D13: 4177621 | E13: =IFS(LEN(D13)=6,CONCAT("0482",D13),LEN(D13)=7,CONCAT("048",D13)) -> 0484177621 | F13: 484177621
... B24: ='Аркуш11'!C24&" "&'Аркуш11'!D24&" "&'Аркуш11'!E24 -> Сапега Никита Александрович | C24: ='Аркуш11'!K24 -> 7718190 | D24: 7718190 | E24: =IFS(LEN(D24)=6,CONCAT("0482",D24),LEN(D24)=7,CONCAT("048",D24)) -> 0487718190 | F24: 487718190
B25: ='Аркуш11'!C25&" "&'Аркуш11'!D25&" "&'Аркуш11'!E25 -> Михайленко Дмитрий Денисович | C25: ='Аркуш11'!K25 -> 5-15-85 | D25: 5-15-85 | E25: =IFS(LEN(D25)=6,CONCAT("0482",D25),LEN(D25)=7,CONCAT("048",D25)) -> 0485-15-85 | F25: 0485-15-85
B26: ='Аркуш11'!C26&" "&'Аркуш11'!D26&" "&'Аркуш11'!E26 -> Леончик Вероника Евгеньевна | C26: ='Аркуш11'!K26 -> 8553582 | D26: 8553582 | E26: =IFS(LEN(D26)=6,CONCAT("0482",D26),LEN(D26)=7,CONCAT("048",D26)) -> 0488553582 | F26: 488553582
B27: ='Аркуш11'!C27&" "&'Аркуш11'!D27&" "&'Аркуш11'!E27 -> Бондарь Антон Викторович | C27: ='Аркуш11'!K27 -> 3579004 | D27: 3579004 | E27: =IFS(LEN(D27)=6,CONCAT("0482",D27),LEN(D27)=7,CONCAT("048",D27)) -> 0483579004 | F27: 483579004
B28: ='Аркуш11'!C28&" "&'Аркуш11'!D28&" "&'Аркуш11'!E28 -> Нефедов Микола Геннадійович | C28: ='Аркуш11'!K28 -> 8690452 | D28: 8690452 | E28: =IFS(LEN(D28)=6,CONCAT("0482",D28),LEN(D28)=7,CONCAT("048",D28)) -> 0488690452 | F28: 488690452
B29: ='Аркуш11'!C29&" "&'Аркуш11'!D29&" "&'Аркуш11'!E29 -> Тучков Егор Денисович | C29: ='Аркуш11'!K29 -> 6347028 | D29: 6347028 | E29: =IFS(LEN(D29)=6,CONCAT("0482",D29),LEN(D29)=7,CONCAT("048",D29)) -> 0486347028 | F29: 486347028
B30: ='Аркуш11'!C30&" "&'Аркуш11'!D30&" "&'Аркуш11'!E30 -> Запрудский Виктор Витальевич | C30: ='Аркуш11'!K30 -> 9323072 | D30: 9323072 | E30: =IFS(LEN(D30)=6,CONCAT("0482",D30),LEN(D30)=7,CONCAT("048",D30)) -> 0489323072 | F30: 489323072
B31: ='Аркуш11'!C31&" "&'Аркуш11'!D31&" "&'Аркуш11'!E31 -> Власенко Андрей Андреевич | C31: ='Аркуш11'!K31 -> 2929706 | D31: 2929706 | E31: =IFS(LEN(D31)=6,CONCAT("0482",D31),LEN(D31)=7,CONCAT("048",D31)) -> 0482929706 | F31: 482929706
B32: ='Аркуш11'!C32&" "&'Аркуш11'!D32&" "&'Аркуш11'!E32 -> Кавалеров Владимир Владимирович | C32: ='Аркуш11'!K32 -> 3-06-87 | D32: 31931 | E32: =IFS(LEN(D32)=6,CONCAT("0482",D32),LEN(D32)=7,CONCAT("048",D32)) -> #N/A | F32: #N/A
B33: ='Аркуш11'!C33&" "&'Аркуш11'!D33&" "&'Аркуш11'!E33 -> Евдокимов Сергей Петрович | C33: ='Аркуш11'!K33 -> 4989647 | D33: 4989647 | E33: =IFS(LEN(D33)=6,CONCAT("0482",D33),LEN(D33)=7,CONCAT("048",D33)) -> 0484989647 | F33: 484989647
B34: ='Аркуш11'!C34&" "&'Аркуш11'!D34&" "&'Аркуш11'!E34 -> Фернандес де Ривес Николай Сергеевич | C34: ='Аркуш11'!K34 -> 1361567 | D34: 1361567 | E34: =IFS(LEN(D34)=6,CONCAT("0482",D34),LEN(D34)=7,CONCAT("048",D34)) -> 0481361567 | F34: 481361567
B35: ='Аркуш11'!C35&" "&'Аркуш11'!D35&" "&'Аркуш11'!E35 -> Степовой Владислав Юрьевич | C35: ='Аркуш11'!K35 -> 9209211 | D35: 9209211 | E35: =IFS(LEN(D35)=6,CONCAT("0482",D35),LEN(D35)=7,CONCAT("048",D35)) -> 0489209211 | F35: 489209211
B36: ='Аркуш11'!C36&" "&'Аркуш11'!D36&" "&'Аркуш11'!E36 -> Сурай Алексей Николаевич | C36: ='Аркуш11'!K36 -> 4880197 | D36: 4880197 | E36: =IFS(LEN(D36)=6,CONCAT("0482",D36),LEN(D36)=7,CONCAT("048",D36)) -> 0484880197 | F36: 484880197
B37: ='Аркуш11'!C37&" "&'Аркуш11'!D37&" "&'Аркуш11'!E37 -> Остапчук Константин Андреевич | C37: ='Аркуш11'!K37 -> 5130125 | D37: 5130125 | E37: =IFS(LEN(D37)=6,CONCAT("0482",D37),LEN(D37)=7,CONCAT("048",D37)) -> 0485130125 | F37: 485130125
B38: ='Аркуш11'!C38&" "&'Аркуш11'!D38&" "&'Аркуш11'!E38 -> Чачко Натан Леонидович | C38: ='Аркуш11'!K38 -> 9792811 | D38: 9792811 | E38: =IFS(LEN(D38)=6,CONCAT("0482",D38),LEN(D38)=7,CONCAT("048",D38)) -> 0489792811 | F38: 489792811
B39: ='Аркуш11'!C39&" "&'Аркуш11'!D39&" "&'Аркуш11'!E39 -> Хмелевский Никита Олегович | C39: ='Аркуш11'!K39 -> 4861520 | D39: 4861520 | E39: =IFS(LEN(D39)=6,CONCAT("0482",D39),LEN(D39)=7,CONCAT("048",D39)) -> 0484861520 | F39: 484861520
B40: ='Аркуш11'!C40&" "&'Аркуш11'!D40&" "&'Аркуш11'!E40 -> Примикирио Дина Витальевна | C40: ='Аркуш11'!K40 -> 6187270 | D40: 6187270 | E40: =IFS(LEN(D40)=6,CONCAT("0482",D40),LEN(D40)=7,CONCAT("048",D40)) -> 0486187270 | F40: 486187270
B41: ='Аркуш11'!C41&" "&'Аркуш11'!D41&" "&'Аркуш11'!E41 -> Костина Лариса Павловна | C41: ='Аркуш11'!K41 -> 1228716 | D41: 1228716 | E41: =IFS(LEN(D41)=6,CONCAT("0482",D41),LEN(D41)=7,CONCAT("048",D41)) -> 0481228716 | F41: 481228716
B42: ='Аркуш11'!C42&" "&'Аркуш11'!D42&" "&'Аркуш11'!E42 -> Прокоп Артём Сергеевич | C42: ='Аркуш11'!K42 -> 9494201 | D42: 9494201 | E42: =IFS(LEN(D42)=6,CONCAT("0482",D42),LEN(D42)=7,CONCAT("048",D42)) -> 0489494201 | F42: 489494201
B43: ='Аркуш11'!C43&" "&'Аркуш11'!D43&" "&'Аркуш11'!E43 -> Гриб Дарья Сергеевна | C43: ='Аркуш11'!K43 -> 1180518 | D43: 1180518 | E43: =IFS(LEN(D43)=6,CONCAT("0482",D43),LEN(D43)=7,CONCAT("048",D43)) -> 0481180518 | F43: 481180518
B44: ='Аркуш11'!C44&" "&'Аркуш11'!D44&" "&'Аркуш11'!E44 -> Чуб Максим Андреевич | C44: ='Аркуш11'!K44 -> 7164943 | D44: 7164943 | E44: =IFS(LEN(D44)=6,CONCAT("0482",D44),LEN(D44)=7,CONCAT("048",D44)) -> 0487164943 | F44: 487164943
... B47: ='Аркуш11'!C47&" "&'Аркуш11'!D47&" "&'Аркуш11'!E47 -> Максименко Николай Сергеевич | C47: ='Аркуш11'!K47 -> 9763553 | D47: 9763553 | E47: =IFS(LEN(D47)=6,CONCAT("0482",D47),LEN(D47)=7,CONCAT("048",D47)) -> 0489763553 | F47: 489763553
B48: ='Аркуш11'!C48&" "&'Аркуш11'!D48&" "&'Аркуш11'!E48 -> Лях Влад Дмитриевич | C48: ='Аркуш11'!K48 -> -32-702 | D48: -32-702 | E48: =IFS(LEN(D48)=6,CONCAT("0482",D48),LEN(D48)=7,CONCAT("048",D48)) -> 048-32-702 | F48: 048-32-702
B49: ='Аркуш11'!C49&" "&'Аркуш11'!D49&" "&'Аркуш11'!E49 -> Флоря Максим Геннадиевич | C49: ='Аркуш11'!K49 -> 0865611 | D49: 865611 | E49: =IFS(LEN(D49)=6,CONCAT("0482",D49),LEN(D49)=7,CONCAT("048",D49)) -> 0482865611 | F49: 482865611
B50: ='Аркуш11'!C50&" "&'Аркуш11'!D50&" "&'Аркуш11'!E50 -> Гуренко Анастасия Константиновна | C50: ='Аркуш11'!K50 -> 1-13-05 | D50: 1-13-05 | E50: =IFS(LEN(D50)=6,CONCAT("0482",D50),LEN(D50)=7,CONCAT("048",D50)) -> 0481-13-05 | F50: 0481-13-05
B51: ='Аркуш11'!C51&" "&'Аркуш11'!D51&" "&'Аркуш11'!E51 -> Комыш Богдан Юрьевич | C51: ='Аркуш11'!K51 -> 9756732 | D51: 9756732 | E51: =IFS(LEN(D51)=6,CONCAT("0482",D51),LEN(D51)=7,CONCAT("048",D51)) -> 0489756732 | F51: 489756732
B52: ='Аркуш11'!C52&" "&'Аркуш11'!D52&" "&'Аркуш11'!E52 -> Хромов Евгений Александрович | C52: ='Аркуш11'!K52 -> 9964190 | D52: 9964190 | E52: =IFS(LEN(D52)=6,CONCAT("0482",D52),LEN(D52)=7,CONCAT("048",D52)) -> 0489964190 | F52: 489964190
...

Sheet Аркуш11
B1: Отметка времени | C1: Фамилия | D1: Имя | E1: Отчество | F1: Школа | G1: Класс | H1: e-mail | I1: Телефон | J1: Укажите, пожалуйста, наиболее удобный способ связи с Вами | K1: Телефон
A2: 1 | B2: 43131.852 | C2: Епифанов | D2: Иван | E2: Алексеевич | F2: ОСШ#17 | G2: 7 | H2: oepifanova74@gmail.com | I2: 509756324 | J2: Телефон | K2: =RIGHT(I2,7) -> 9756324 | L2: =RIGHT(K2,6) -> 756324
A3: 2 | B3: 43131.894 | C3: Балочкин | D3: Игорь | E3: Вадимович | F3: 17 | G3: 7 | H3: uaigor2005@gmail.com | I3: 972175876 | J3: Viber | K3: =RIGHT(I3,7) -> 2175876 | L3: =RIGHT(K3,6) -> 175876
A4: 3 | B4: 43132.463 | C4: Кувшинов | D4: Виктор | E4: Евгеньевич | F4: 17 | G4: 7 | H4: elenakuvsh@rambler.ru | I4: 974847540 | J4: Viber | K4: =RIGHT(I4,7) -> 4847540 | L4: =RIGHT(K4,6) -> 847540
A5: 4 | B5: 43133.551 | C5: Бобошко | D5: Максим | E5: Михайлович | F5: 17 | G5: 7 | H5: pufa2307@gmail.com | I5: 677235957 | J5: Телефон | K5: =RIGHT(I5,7) -> 7235957 | L5: =RIGHT(K5,6) -> 235957
A6: 5 | B6: 43134.525 | C6: Павлюкова | D6: Елизавета | E6: Владимировна | F6: ОСШ 17 | G6: 7 | H6: lizapavlyukovaa@gmail.com | I6: +380679221389 | J6: Телефон | K6: =RIGHT(I6,7) -> 9221389 | L6: =RIGHT(K6,6) -> 221389
A7: 6 | B7: 43134.933 | C7: Гаврилюк | D7: Юрий | E7: Валентинович | F7: Выпаснянская общеобразовательная школа №1 | G7: 8 | H7: ugavriluk90@gmail.com | I7: +380685008696 | J7: Телефон | K7: =RIGHT(I7,7) -> 5008696 | L7: =RIGHT(K7,6) -> 008696
A8: 7 | B8: 43135.614 | C8: Изотова | D8: Ирина | E8: Александровна | F8: Гимназия 5 | G8: 10 | H8: iraizotova443@gmail.com | I8: +380668805222 | J8: Viber | K8: =RIGHT(I8,7) -> 8805222 | L8: =RIGHT(K8,6) -> 805222
A9: 8 | B9: 43135.657 | C9: Сторожев | D9: Олег | E9: Игоревич | F9: Одесский юридический лицей | G9: 10 | H9: storozheva@i.ua | I9: +380637352238 | J9: e-mail | K9: =RIGHT(I9,7) -> 7352238 | L9: =RIGHT(K9,6) -> 352238
A10: 9 | B10: 43136.794 | C10: Спивак | D10: Максим | E10: Игоревич | F10: ОСШ 17 | G10: 7 | H10: spivakmaks18@Gmail. com | I10: 673961683 | J10: Телефон | K10: =RIGHT(I10,7) -> 3961683 | L10: =RIGHT(K10,6) -> 961683
A11: 10 | B11: 43136.794 | C11: Спивак | D11: Максим | E11: Игоревич | F11: ОСШ 17 | G11: 7 | H11: spivakmaks18@Gmail. com | I11: 673961683 | J11: Телефон | K11: =RIGHT(I11,7) -> 3961683 | L11: =RIGHT(K11,6) -> 961683
A12: 11 | B12: 43138.765 | C12: Епифанов | D12: Иван | E12: Алексеевич | F12: ОСШ 17 | G12: 7 | H12: oepifanova74@gmail.com | I12: 509756324 | J12: Viber | K12: =RIGHT(I12,7) -> 9756324 | L12: =RIGHT(K12,6) -> 756324
A13: 12 | B13: 43142.889 | C13: Дуганов | D13: Костя | E13: Вячеславович | F13: 17 | G13: 7 | H13: kost3480@gmail.com | I13: +380674177621 | J13: Телефон | K13: =RIGHT(I13,7) -> 4177621 | L13: =RIGHT(K13,6) -> 177621
A14: 13 | B14: 43152.64 | C14: Юрескул | D14: Дарья | E14: Юрьевна | F14: ВознесенскаяООШ№10 | G14: 10 | H14: yureskuldasha@gmail.com | I14: +380990181270 | J14: Viber | K14: =RIGHT(I14,7) -> 0181270 | L14: =RIGHT(K14,6) -> 181270
A15: 14 | B15: 43158.517 | C15: Бобошко | D15: Максим | E15: Михайлович | F15: 17 | G15: 7 | H15: marantz2110@gmail.com | I15: +380980424742 | J15: Viber | K15: =RIGHT(I15,7) -> 0424742 | L15: =RIGHT(K15,6) -> 424742
A16: 15 | B16: 43170.806 | C16: Габчак | D16: Ольга | E16: Александровна | F16: 13 | G16: 7 | H16: abkandbbm@ukr.net | I16: 683898299 | J16: Телефон | K16: =RIGHT(I16,7) -> 3898299 | L16: =RIGHT(K16,6) -> 898299
A17: 16 | B17: 43178.333 | C17: Станкевич | D17: Даниил | E17: Дмитриевич | F17: 17 | G17: 7 | H17: vika80zagmail.com | I17: 982204010 | J17: Телефон | K17: =RIGHT(I17,7) -> 2204010 | L17: =RIGHT(K17,6) -> 204010
A18: 17 | B18: 43178.806 | C18: Коджебаш | D18: Никита | E18: Сергеевич | F18: OCШ №17 | G18: 7 | H18: JustNekit32854@gmail.com | I18: 380969205729 | J18: Телефон | K18: =RIGHT(I18,7) -> 9205729 | L18: =RIGHT(K18,6) -> 205729
A19: 18 | B19: 43178.846 | C19: Паладий | D19: Владислав | E19: Григорьевич | F19: 17 | G19: 7 | H19: tanyapaladiu81@gmail.com | I19: 960790437 | J19: Телефон | K19: =RIGHT(I19,7) -> 0790437 | L19: =RIGHT(K19,6) -> 790437
A20: 19 | B20: 43179.603 | C20: Сергатий | D20: Евгений | E20: Юрійович | F20: Виктория -П м.Кропивницький | G20: 10 | H20: TSergati76@i.ua | I20: 667437733 | J20: Телефон | K20: =RIGHT(I20,7) -> 7437733 | L20: =RIGHT(K20,6) -> 437733
A21: 20 | B21: 43179.887 | C21: Паладий | D21: Влад | E21: Григорьевич | F21: 17 | G21: 7 | H21: tanyapaladiu81@gmail. com | I21: 960790437 | J21: Телефон | K21: =RIGHT(I21,7) -> 0790437 | L21: =RIGHT(K21,6) -> 790437
A22: 21 | B22: 43193.728 | C22: Дыкусар | D22: Максим | E22: Игоревич | F22: Мариинская гимназия | G22: 7 | H22: sashakoupchak@gmail.com | I22: 982141839 | J22: Телефон | K22: =RIGHT(I22,7) -> 2141839 | L22: =RIGHT(K22,6) -> 141839
A23: 22 | B23: 43194.451 | C23: Тучков | D23: Иван | E23: Денисович | F23: Ришельевский лицей | G23: 9 | H23: tuchkov.ivan@rl.odessa.ua | I23: 972168316 | J23: Telegram | K23: =RIGHT(I23,7) -> 2168316 | L23: =RIGHT(K23,6) -> 168316
A24: 23 | B24: 43194.451 | C24: Сапега | D24: Никита | E24: Александрович | F24: Ришельевский лицей | G24: 9 | H24: niksapeg@gmail.com | I24: 997718190 | J24: Viber | K24: =RIGHT(I24,7) -> 7718190 | L24: =RIGHT(K24,6) -> 718190
A25: 24 | B25: 43197.76 | C25: Михайленко | D25: Дмитрий | E25: Денисович | F25: Одесский юридический лицей | G25: 10 | H25: mariym1602@gmail.com | I25: 050-495-15-85 | J25: Телефон | K25: =RIGHT(I25,7) -> 5-15-85 | L25: =RIGHT(K25,6) -> -15-85
A26: 25 | B26: 43198.368 | C26: Леончик | D26: Вероника | E26: Евгеньевна | F26: Ришельевский Лицей | G26: 7 | H26: leonchik@ukr.net | I26: 6678553582 | J26: Viber | K26: =RIGHT(I26,7) -> 8553582 | L26: =RIGHT(K26,6) -> 553582
A27: 26 | B27: 43200.439 | C27: Бондарь | D27: Антон | E27: Викторович | F27: Ришельевский лицей | G27: 7 | H27: e. vladimirovna7666@gmail. com | I27: 963579004 | J27: Телефон | K27: =RIGHT(I27,7) -> 3579004 | L27: =RIGHT(K27,6) -> 579004
A28: 27 | B28: 43200.82 | C28: Нефедов | D28: Микола | E28: Геннадійович | F28: Рішельєвський ліцей | G28: 7 | H28: nickolay.nefed@gmail.com | I28: +380988690452 | J28: Telegram | K28: =RIGHT(I28,7) -> 8690452 | L28: =RIGHT(K28,6) -> 690452
A29: 28 | B29: 43200.857 | C29: Тучков | D29: Егор | E29: Денисович | F29: Ришельевский лицей | G29: 8 | H29: egorys2000@yandex.ru | I29: +380666347028 | J29: Viber | K29: =RIGHT(I29,7) -> 6347028 | L29: =RIGHT(K29,6) -> 347028
A30: 29 | B30: 43200.863 | C30: Запрудский | D30: Виктор | E30: Витальевич | F30: РЛ | G30: 8 | H30: zviktor05@mail.ru | I30: 949323072 | J30: Telegram | K30: =RIGHT(I30,7) -> 9323072 | L30: =RIGHT(K30,6) -> 323072
A31: 30 | B31: 43200.873 | C31: Власенко | D31: Андрей | E31: Андреевич | F31: Ришельевский лицей | G31: 8 | H31: vlasenko_andrij@rl.odessa.ua | I31: 380972929706 | J31: Telegram | K31: =RIGHT(I31,7) -> 2929706 | L31: =RIGHT(K31,6) -> 929706
A32: 31 | B32: 43200.884 | C32: Кавалеров | D32: Владимир | E32: Владимирович | F32: Ришельевский лицей | G32: 8 | H32: vdkavalerova@ukr.net | I32: 067-723-06-87 | J32: Viber | K32: =RIGHT(I32,7) -> 3-06-87 | L32: =RIGHT(K32,6) -> -06-87
A33: 32 | B33: 43200.95 | C33: Евдокимов | D33: Сергей | E33: Петрович | F33: Школа №27 | G33: 10 | H33: yevdokymov@ukr.net | I33: 380984989647 | J33: Telegram | K33: =RIGHT(I33,7) -> 4989647 | L33: =RIGHT(K33,6) -> 989647
A34: 33 | B34: 43201.451 | C34: Фернандес де Ривес | D34: Николай | E34: Сергеевич | F34: Мариинская гимназия | G34: 8 | H34: sa.zanoza@gmail.com | I34: 631361567 | J34: Telegram | K34: =RIGHT(I34,7) -> 1361567 | L34: =RIGHT(K34,6) -> 361567
A35: 34 | B35: 43201.715 | C35: Степовой | D35: Владислав | E35: Юрьевич | F35: 13 | G35: 9 | H35: stepovaya@gmail.com | I35: 679209211 | J35: Телефон | K35: =RIGHT(I35,7) -> 9209211 | L35: =RIGHT(K35,6) -> 209211
A36: 35 | B36: 43201.869 | C36: Сурай | D36: Алексей | E36: Николаевич | F36: 8 гимназия | G36: 8 | H36: okeanisniko2007@ gmail.com | I36: 674880197 | J36: Телефон | K36: =RIGHT(I36,7) -> 4880197 | L36: =RIGHT(K36,6) -> 880197
A37: 36 | B37: 43201.96 | C37: Остапчук | D37: Константин | E37: Андреевич | F37: Ришельевский лицей | G37: 7 | H37: Sofolga@yahoo.com | I37: 505130125 | J37: Viber | K37: =RIGHT(I37,7) -> 5130125 | L37: =RIGHT(K37,6) -> 130125
A38: 37 | B38: 43202.325 | C38: Чачко | D38: Натан | E38: Леонидович | F38: УВК Хабад | G38: 9 | H38: neylyn951@gmail.com | I38: 509792811 | J38: Telegram | K38: =RIGHT(I38,7) -> 9792811 | L38: =RIGHT(K38,6) -> 792811
A39: 38 | B39: 43202.397 | C39: Хмелевский | D39: Никита | E39: Олегович | F39: Ришельевский лицей | G39: 7 | H39: luba_od@rambler.ru | I39: +380674861520 | J39: e-mail | K39: =RIGHT(I39,7) -> 4861520 | L39: =RIGHT(K39,6) -> 861520
A40: 39 | B40: 43202.423 | C40: Примикирио | D40: Дина | E40: Витальевна | F40: 117 | G40: 10 | H40: d.v.primikirio@gmail.com | I40: 666187270 | J40: Телефон | K40: =RIGHT(I40,7) -> 6187270 | L40: =RIGHT(K40,6) -> 187270
...
